Workbook

Sheet Lbs by island
A1: year | B1: island | C1: island.code | D1: island.weight | E1: lbs.total
A2: 2005 | B2: hawaii | C2: =IF(B2="hawaii",1) -> 1 | D2: 0.32673516 | E2: ='Total lbs'!B2*D2 -> 55427.708
A3: 2005 | B3: kauai | C3: 2 | D3: 0.07974173 | E3: ='Total lbs'!B2*D3 -> 13527.474
A4: 2005 | B4: lanai | C4: 3 | D4: 0.0092211614 | E4: ='Total lbs'!B2*D4 -> 1564.2878
A5: 2005 | B5: maui | C5: 4 | D5: 0.14533885 | E5: ='Total lbs'!B2*D5 -> 24655.441
A6: 2005 | B6: molokai | C6: 5 | D6: 0.079009165 | E6: ='Total lbs'!B2*D6 -> 13403.201
A7: 2005 | B7: oahu | C7: 6 | D7: 0.35995393 | E7: ='Total lbs'!B2*D7 -> 61062.976
A8: 2006 | B8: hawaii | C8: 1 | D8: 0.32673516 | E8: ='Total lbs'!B3*D8 -> 92568.798
A9: 2006 | B9: kauai | C9: 2 | D9: 0.07974173 | E9: ='Total lbs'!B3*D9 -> 22591.986
A10: 2006 | B10: lanai | C10: 3 | D10: 0.0092211614 | E10: ='Total lbs'!B3*D10 -> 2612.4884
A11: 2006 | B11: maui | C11: 4 | D11: 0.14533885 | E11: ='Total lbs'!B3*D11 -> 41176.599
A12: 2006 | B12: molokai | C12: 5 | D12: 0.079009165 | E12: ='Total lbs'!B3*D12 -> 22384.439
A13: 2006 | B13: oahu | C13: 6 | D13: 0.35995393 | E13: ='Total lbs'!B3*D13 -> 101980.16
A14: 2007 | B14: hawaii | C14: 1 | D14: 0.32673516 | E14: ='Total lbs'!B4*D14 -> 78890.55
A15: 2007 | B15: kauai | C15: 2 | D15: 0.07974173 | E15: ='Total lbs'!B4*D15 -> 19253.725
A16: 2007 | B16: lanai | C16: 3 | D16: 0.0092211614 | E16: ='Total lbs'!B4*D16 -> 2226.4592
A17: 2007 | B17: maui | C17: 4 | D17: 0.14533885 | E17: ='Total lbs'!B4*D17 -> 35092.219
A18: 2007 | B18: molokai | C18: 5 | D18: 0.079009165 | E18: ='Total lbs'!B4*D18 -> 19076.846
A19: 2007 | B19: oahu | C19: 6 | D19: 0.35995393 | E19: ='Total lbs'!B4*D19 -> 86911.257
A20: 2008 | B20: hawaii | C20: 1 | D20: 0.32673516 | E20: ='Total lbs'!B5*D20 -> 73599.02
A21: 2008 | B21: kauai | C21: 2 | D21: 0.07974173 | E21: ='Total lbs'!B5*D21 -> 17962.294
A22: 2008 | B22: lanai | C22: 3 | D22: 0.0092211614 | E22: ='Total lbs'!B5*D22 -> 2077.1209
A23: 2008 | B23: maui | C23: 4 | D23: 0.14533885 | E23: ='Total lbs'!B5*D23 -> 32738.433
A24: 2008 | B24: molokai | C24: 5 | D24: 0.079009165 | E24: ='Total lbs'!B5*D24 -> 17797.28
A25: 2008 | B25: oahu | C25: 6 | D25: 0.35995393 | E25: ='Total lbs'!B5*D25 -> 81081.743
A26: 2009 | B26: hawaii | C26: 1 | D26: 0.32673516 | E26: ='Total lbs'!B6*D26 -> 55032.051
A27: 2009 | B27: kauai | C27: 2 | D27: 0.07974173 | E27: ='Total lbs'!B6*D27 -> 13430.911
A28: 2009 | B28: lanai | C28: 3 | D28: 0.0092211614 | E28: ='Total lbs'!B6*D28 -> 1553.1215
A29: 2009 | B29: maui | C29: 4 | D29: 0.14533885 | E29: ='Total lbs'!B6*D29 -> 24479.444
A30: 2009 | B30: molokai | C30: 5 | D30: 0.079009165 | E30: ='Total lbs'!B6*D30 -> 13307.525
A31: 2009 | B31: oahu | C31: 6 | D31: 0.35995393 | E31: ='Total lbs'!B6*D31 -> 60627.093
A32: 2010 | B32: hawaii | C32: 1 | D32: 0.32673516 | E32: ='Total lbs'!B7*D32 -> 85112.195
A33: 2010 | B33: kauai | C33: 2 | D33: 0.07974173 | E33: ='Total lbs'!B7*D33 -> 20772.156
A34: 2010 | B34: lanai | C34: 3 | D34: 0.0092211614 | E34: ='Total lbs'!B7*D34 -> 2402.0472
A35: 2010 | B35: maui | C35: 4 | D35: 0.14533885 | E35: ='Total lbs'!B7*D35 -> 37859.741
A36: 2010 | B36: molokai | C36: 5 | D36: 0.079009165 | E36: ='Total lbs'!B7*D36 -> 20581.328
A37: 2010 | B37: oahu | C37: 6 | D37: 0.35995393 | E37: ='Total lbs'!B7*D37 -> 93765.449
A38: 2011 | B38: hawaii | C38: 1 | D38: 0.32673516 | E38: ='Total lbs'!B8*D38 -> 45437.491
A39: 2011 | B39: kauai | C39: 2 | D39: 0.07974173 | E39: ='Total lbs'!B8*D39 -> 11089.3
A40: 2011 | B40: lanai | C40: 3 | D40: 0.0092211614 | E40: ='Total lbs'!B8*D40 -> 1282.3427
...

Sheet Total lbs
A1: year | B1: lbs | C1: lbs.se | D1: approx.ev
A2: 2005 | B2: 169641.09 | C2: 24643.561 | D2: =3.93*B2-0.95*B2 -> 505530.44
A3: 2006 | B3: 283314.47 | C3: 49129.622 | D3: =3.93*B3-0.95*B3 -> 844277.11
A4: 2007 | B4: 241451.06 | C4: 39369.565 | D4: =3.93*B4-0.95*B4 -> 719524.15
A5: 2008 | B5: 225255.89 | C5: 36273.137 | D5: =3.93*B5-0.95*B5 -> 671262.55
A6: 2009 | B6: 168430.15 | C6: 20119.965 | D6: =3.93*B6-0.95*B6 -> 501921.83
A7: 2010 | B7: 260492.92 | C7: 43886.361 | D7: =3.93*B7-0.95*B7 -> 776268.89
A8: 2011 | B8: 139065.2 | C8: 13590.168 | D8: =3.93*B8-0.95*B8 -> 414414.3
A9: 2012 | B9: 214786.5 | C9: 34264.164 | D9: =3.93*B9-0.95*B9 -> 640063.76
A10: 2013 | B10: 234129.03 | C10: 33052.385 | D10: =3.93*B10-0.95*B10 -> 697704.51
A11: 2014 | B11: 229987.41 | C11: 21558.88 | D11: =3.93*B11-0.95*B11 -> 685362.47
A12: 2015 | B12: 177036.38 | C12: 21923.723 | D12: =3.93*B12-0.95*B12 -> 527568.41
A13: 2016 | B13: 156372.56 | C13: 11821.837 | D13: =3.93*B13-0.95*B13 -> 465990.22
... A19: 2022 | B19: 145076.88 | C19: 30624.919 | D19: =3.93*B19-0.95*B19 -> 432329.11
D20: =AVERAGE(D2:D19) -> 617302.48

Sheet Island code key
A1: island | B1: island.code | C1: island.weight
A2: Hawaii | B2: 1 | C2: =321131/SUM(321131,78374,9063,142846,77654,353780) -> 0.32673516
A3: Kauai | B3: 2 | C3: =78374/SUM(321131,78374,9063,142846,77654,353780) -> 0.07974173
A4: Lanai | B4: 3 | C4: =9063/SUM(321131,78374,9063,142846,77654,353780) -> 0.0092211614
A5: Maui | B5: 4 | C5: =142846/SUM(321131,78374,9063,142846,77654,353780) -> 0.14533885
A6: Molokai | B6: 5 | C6: =77654/SUM(321131,78374,9063,142846,77654,353780) -> 0.079009165
A7: Oahu | B7: 6 | C7: =353780/SUM(321131,78374,9063,142846,77654,353780) -> 0.35995393
